Workbook

Sheet Eventos
A1: ID | B1: Código | C1: Título | D1: Resumen | E1: Tipo de evento | F1: Estado | G1: Municipio | H1: Inicio | I1: Última actualización | J1: Estado del evento | K1: Prioridad | L1: Puntaje | M1: Revisión | N1: Actores | O1: Número de fuentes | P1: Motivos del puntaje
A2: 1 | B2: SMEE-20260801-FC0313F6 | C2: Planeará y organizará INE más de 500 actividades del Proceso Electoral Federal 2026‑2027 | D2: Instituto Nacional Electoral: número: 330 El inicio está previsto para el próximo 10 de septiembre. La información se inscribe en la publicación de un calendario electoral en Nacional, involucrando a ningún partido identificado en el ciclo electoral de 2026-2027. | E2: Publicación oficial de calendario electoral | F2: Nacional | H2: 46235.004 | I2: 46235.004 | J2: detected | K2: Alto | L2: 13 | M2: No | N2: Instituto Nacional Electoral | O2: =COUNTIF('Publicaciones'!$B$2:$B$51,B2) | P2: Tipo 'Publicación oficial de calendario electoral': +8 · Fuente oficial: +5
A3: 12 | B3: SMEE-20260802-8E279CC1 | C3: Cuatro finalistas de Morena avanzan a la encuesta estatal en CDMX | D3: Cuatro finalistas de Morena avanzan a la encuesta estatal en CDMX. Esta información se inscribe en una encuesta de preferencias electorales en Ciudad de México, involucrando a Morena en el ciclo 2027 según lo publicado por la fuente consultada. | E3: Nueva encuesta | F3: Ciudad de México | H3: 46236.954 | I3: 46236.954 | J3: detected | K3: Medio | L3: 8 | M3: No | O3: =COUNTIF('Publicaciones'!$B$2:$B$51,B3) | P3: Tipo 'Nueva encuesta': +8
A4: 13 | B4: SMEE-20260802-9DEC0C3C | C4: Nuevo León: morenistas inician contienda por gubernatura 2027 | D4: Cuatro aspirantes de Morena compiten por la candidatura a la gubernatura en un entorno electoral atípico. Este acontecimiento se relaciona con un registro o anuncio de candidatura en Nuevo León; los actores vinculados son Morena, en la ruta electoral de 2027. | E4: Registro o anuncio de candidatura | F4: Nuevo León | H4: 46236.713 | I4: 46236.713 | J4: detected | K4: Medio | L4: 8 | M4: No | O4: =COUNTIF('Publicaciones'!$B$2:$B$51,B4) | P4: Tipo 'Registro o anuncio de candidatura': +8
A5: 15 | B5: SMEE-20260801-9279F5F3 | C5: Morena define rumbo en Michoacán para candidatura gubernamental | D5: Morena define rumbo en Michoacán para candidatura gubernamental. Este acontecimiento se relaciona con un registro o anuncio de candidatura en Michoacán; los actores vinculados son Morena, en la ruta electoral de 2027 según lo publicado por la fuente consultada. | E5: Registro o anuncio de candidatura | F5: Michoacán | G5: Morelia | H5: 46235.85 | I5: 46235.85 | J5: detected | K5: Medio | L5: 8 | M5: No | O5: =COUNTIF('Publicaciones'!$B$2:$B$51,B5) | P5: Tipo 'Registro o anuncio de candidatura': +8
A6: 2 | B6: SMEE-20260803-910904DC | C6: Colosio y Astiazarán buscan alianza en la gubernatura de Sonora | D6: Colosio y Astiazarán buscan alianza en la gubernatura de Sonora. Este evento corresponde a un hecho relacionado con el proceso electoral en Sonora, donde se identifica a ningún partido identificado dentro del calendario electoral de 2027. | E6: Otro evento electoral | F6: Sonora | H6: 46237.684 | I6: 46237.684 | J6: detected | K6: Bajo | L6: 3 | M6: No | O6: =COUNTIF('Publicaciones'!$B$2:$B$51,B6) | P6: Tipo 'Otro evento electoral': +3
A7: 3 | B7: SMEE-20260803-9A509C17 | C7: Mario García espera los tiempos para definir su futuro político | D7: Mario García espera los tiempos para definir su futuro político. El hecho se ubica en el contexto de un hecho relacionado con el proceso electoral en Chihuahua, con mención de PAN, en el proceso electoral de 2027. | E7: Otro evento electoral | F7: Chihuahua | G7: Chihuahua | H7: 46237.661 | I7: 46237.661 | J7: detected | K7: Bajo | L7: 3 | M7: No | O7: =COUNTIF('Publicaciones'!$B$2:$B$51,B7) | P7: Tipo 'Otro evento electoral': +3
A8: 4 | B8: SMEE-20260803-7A52522F | C8: Evaluarán votación en Ceresos para elecciones de 2027 en Chihuahua | D8: Evaluarán votación en Ceresos para elecciones de 2027 en Chihuahua. Este evento corresponde a un hecho relacionado con el proceso electoral en Chihuahua, donde se identifica a PAN dentro del calendario electoral de 2027 según lo publicado por la fuente consultada. | E8: Otro evento electoral | F8: Chihuahua | G8: Chihuahua | H8: 46237.643 | I8: 46237.643 | J8: detected | K8: Bajo | L8: 3 | M8: No | O8: =COUNTIF('Publicaciones'!$B$2:$B$51,B8) | P8: Tipo 'Otro evento electoral': +3
A9: 5 | B9: SMEE-20260803-A2EAB4CA | C9: David Cortés impulsa alianzas y unidad en el PAN de Morelia | D9: David Cortés impulsa alianzas y unidad en el PAN de Morelia. Este evento corresponde a un hecho relacionado con el proceso electoral en Michoacán, donde se identifica a PAN dentro del calendario electoral de 2027. | E9: Otro evento electoral | F9: Michoacán | G9: Morelia | H9: 46237.608 | I9: 46237.608 | J9: detected | K9: Bajo | L9: 3 | M9: No | O9: =COUNTIF('Publicaciones'!$B$2:$B$51,B9) | P9: Tipo 'Otro evento electoral': +3
A10: 19 | B10: SMEE-20260803-21D35497 | C10: “No son tiempos”: Colosio Riojas descarta adelantarse rumbo a una posible candidatura; informará decisión a finales de 2026, dice | D10: El senador de Movimiento Ciudadano, Luis Donaldo Colosio Riojas. El hecho se ubica en el contexto de un hecho relacionado con el proceso electoral en Nuevo León, con mención de Movimiento Ciudadano, en el proceso electoral de 2026. | E10: Otro evento electoral | F10: Nuevo León | H10: 46237.599 | I10: 46237.599 | J10: detected | K10: Bajo | L10: 3 | M10: Sí | O10: =COUNTIF('Publicaciones'!$B$2:$B$51,B10) | P10: Tipo 'Otro evento electoral': +3
A11: 18 | B11: SMEE-20260803-E6C5BB3F | C11: Ulises Mejía Haro consolida ventaja hacia gubernatura | El Universal | D11: Lee también Zacatecas, Puebla y Chiapas con más crecimiento de compradores de autos nuevos. El hecho ocurre en el marco de un registro o anuncio de candidatura en Zacatecas, con la participación de PRI, Morena, Movimiento Ciudadano y Partido del Trabajo de cara al proceso de 2027. | E11: Registro o anuncio de candidatura | F11: Zacatecas | G11: Zacatecas | H11: 46237.595 | I11: 46237.595 | J11: detected | K11: Bajo | L11: 3 | M11: Sí | O11: =COUNTIF('Publicaciones'!$B$2:$B$51,B11) | P11: Tipo 'Registro o anuncio de candidatura': +8 · Publicación duplicada vinculada: -5
A12: 6 | B12: SMEE-20260803-8F80E3E5 | C12: PAN define estrategias electorales: Santiago De la Peña para Chihuahua | D12: PAN define estrategias electorales: Santiago De la Peña para Chihuahua. La información se inscribe en un hecho relacionado con el proceso electoral en Chihuahua, involucrando a PAN en el ciclo electoral de 2027 según lo publicado por la fuente consultada. | E12: Otro evento electoral | F12: Chihuahua | G12: Chihuahua | H12: 46237.577 | I12: 46237.577 | J12: detected | K12: Bajo | L12: 3 | M12: No | O12: =COUNTIF('Publicaciones'!$B$2:$B$51,B12) | P12: Tipo 'Otro evento electoral': +3
A13: 7 | B13: SMEE-20260803-79036C52 | C13: Candidaturas de Morena se afianzan en Chihuahua con nuevos registros | D13: Candidaturas de Morena se afianzan en Chihuahua con nuevos registros. El hecho se ubica en el contexto de un hecho relacionado con el proceso electoral en Chihuahua, con mención de PAN y Morena, en el proceso electoral de 2024. | E13: Otro evento electoral | F13: Chihuahua | G13: Chihuahua | H13: 46237.424 | I13: 46237.424 | J13: detected | K13: Bajo | L13: 3 | M13: Sí | O13: =COUNTIF('Publicaciones'!$B$2:$B$51,B13) | P13: Tipo 'Otro evento electoral': +3
A14: 8 | B14: SMEE-20260803-F0C70DA7 | C14: Morena establece nueva evaluación de candidatos para 2027 | D14: Morena establece nueva evaluación de candidatos para 2027. La información se inscribe en un hecho relacionado con el proceso electoral en Puebla, involucrando a Morena en el ciclo electoral de 2027 según lo publicado por la fuente consultada. | E14: Otro evento electoral | F14: Puebla | G14: Puebla | H14: 46237.306 | I14: 46237.306 | J14: detected | K14: Bajo | L14: 3 | M14: No | O14: =COUNTIF('Publicaciones'!$B$2:$B$51,B14) | P14: Tipo 'Otro evento electoral': +3
A15: 9 | B15: SMEE-20260803-C31C484D | C15: Andrés Manuel López Beltrán recorre Distrito 6 de Tabasco | D15: Andrés Manuel López Beltrán recorre Distrito 6 de Tabasco. El hecho se ubica en el contexto de un hecho relacionado con el proceso electoral en Tabasco, con mención de Morena, en el proceso electoral de 2027. | E15: Otro evento electoral | F15: Tabasco | H15: 46237.235 | I15: 46237.235 | J15: detected | K15: Bajo | L15: 3 | M15: No | O15: =COUNTIF('Publicaciones'!$B$2:$B$51,B15) | P15: Tipo 'Otro evento electoral': +3
A16: 10 | B16: SMEE-20260803-C9DFFDB0 | C16: Andy López Beltrán inicia su camino hacia diputación federal en Tabasco | D16: Andy López Beltrán inicia su camino hacia diputación federal en Tabasco. Este evento corresponde a un hecho relacionado con el proceso electoral en Tabasco, donde se identifica a Morena dentro del calendario electoral de 2027. | E16: Otro evento electoral | F16: Tabasco | H16: 46237.064 | I16: 46237.064 | J16: detected | K16: Bajo | L16: 3 | M16: No | O16: =COUNTIF('Publicaciones'!$B$2:$B$51,B16) | P16: Tipo 'Otro evento electoral': +3
A17: 11 | B17: SMEE-20260803-DF903415 | C17: Carlos Torres Piña consolida su liderazgo en Morelia con 2 mil asistentes | D17: La reunión demuestra la capacidad organizativa de Torres Piña, crucial para el futuro electoral en Michoacán. El hecho se ubica en el contexto de un hecho relacionado con el proceso electoral en Michoacán, con mención de ningún partido identificado, en el proceso electoral de 2027. | E17: Otro evento electoral | F17: Michoacán | G17: Morelia | H17: 46237.056 | I17: 46237.056 | J17: detected | K17: Bajo | L17: 3 | M17: No | O17: =COUNTIF('Publicaciones'!$B$2:$B$51,B17) | P17: Tipo 'Otro evento electoral': +3
A18: 14 | B18: SMEE-20260802-5E507918 | C18: Unidad interna en Morena busca fortalecer candidatura en Chihuahua | D18: Unidad interna en Morena busca fortalecer candidatura en Chihuahua. Este evento corresponde a un hecho relacionado con el proceso electoral en Chihuahua, donde se identifica a Morena dentro del calendario electoral de 2027 según lo publicado por la fuente consultada. | E18: Otro evento electoral | F18: Chihuahua | G18: Chihuahua | H18: 46236.432 | I18: 46236.432 | J18: detected | K18: Bajo | L18: 3 | M18: Sí | O18: =COUNTIF('Publicaciones'!$B$2:$B$51,B18) | P18: Tipo 'Otro evento electoral': +3
A19: 17 | B19: SMEE-20260803-49BC2B07 | C19: Los gobernadores que ya eligieron a su sucesor para 2027: quiénes son los respaldados en los estados | D19: El catedrático de la Universidad de la Ciénega del Estado de Michoacán (UCEMICH) señala que antes –en la época de la hegemonía del PRI– los mandatarios “tenían mano” en la elección de sus sucesores. Este evento corresponde a un hecho relacionado con el proceso electoral en Michoacán, donde se identifica a PRI y Morena dentro del calendario electoral de 2027. | E19: Otro evento electoral | F19: Michoacán | H19: 46237.595 | I19: 46237.595 | J19: detected | K19: Descartable | L19: -2 | M19: Sí | O19: =COUNTIF('Publicaciones'!$B$2:$B$51,B19) | P19: Tipo 'Otro evento electoral': +3 · Publicación duplicada vinculada: -5
A20: 16 | B20: SMEE-20260803-5A7E410C | C20: Morena se reúne con aspirantes a candidaturas para gobernador de Chihuahua, Sinaloa, Sonora y BC | D20: Instituto Nacional Electoral: lee también Gobierno abre consulta para proteger derechos de las audiencias en radio y televisión. La información se inscribe en un hecho relacionado con el proceso electoral en Chihuahua, involucrando a PAN, PRI y Morena en el ciclo electoral de 2027. | E20: Otro evento electoral | F20: Chihuahua | G20: Chihuahua | H20: 46237.595 | I20: 46237.595 | J20: detected | K20: Descartable | L20: -2 | M20: Sí | N20: Instituto Nacional Electoral | O20: =COUNTIF('Publicaciones'!$B$2:$B$51,B20) | P20: Tipo 'Otro evento electoral': +3 · Publicación duplicada vinculada: -5

Sheet Publicaciones
A1: ID | B1: Código del evento | C1: Fuente | D1: Título | E1: Fecha de publicación | F1: Estado | G1: Municipio | H1: Partido | I1: Tipo de evento | J1: Procesamiento | K1: Revisión | L1: Relación | M1: Es fuente primaria | N1: Duplicada | O1: URL | P1: Autor
A2: 43 | C2: Central Electoral INE | D2: Entrevista del Consejero Electoral Uuc-kib Espadas con Carlos Zúñiga para Milenio TV | E2: 46237.847 | J2: review | K2: Sí | M2: No | N2: No | O2: https://centralelectoral.ine.mx/2026/08/03/entrevista-del-consejero-electoral-uuc-kib-espadas-con-carlos-zuniga-para-milenio-tv-5/ | P2: INE
A3: 18 | C3: El Congresista | D3: Morena definirá coordinador de la 4T en Sonora a finales de agosto | E3: 46237.764 | F3: Sonora | H3: Morena | J3: review | K3: Sí | M3: No | N3: No | O3: https://elcongresista.mx/politica/sonora/morena-sonora-encuesta-coordinador-agosto
A4: 19 | B4: SMEE-20260803-910904DC | C4: El Congresista | D4: Colosio y Astiazarán buscan alianza en la gubernatura de Sonora | E4: 46237.684 | F4: Sonora | I4: Otro evento electoral | J4: classified | K4: No | L4: primary_evidence | M4: Sí | N4: No | O4: https://elcongresista.mx/politica/sonora/colosio-astiazaran-alianza-gubernatura-sonora
A5: 1 | C5: Central Electoral INE | D5: Invita INE Michoacán a la ciudadanía a recoger su Credencial para Votar | E5: 46237.667 | F5: Michoacán | J5: review | K5: Sí | M5: No | N5: No | O5: https://centralelectoral.ine.mx/2026/08/03/invita-ine-michoacan-a-la-ciudadania-a-recoger-su-credencial-para-votar/ | P5: Redacción INE
A6: 20 | B6: SMEE-20260803-9A509C17 | C6: El Congresista | D6: Mario García espera los tiempos para definir su futuro político | E6: 46237.661 | F6: Chihuahua | G6: Chihuahua | H6: PAN | I6: Otro evento electoral | J6: classified | K6: No | L6: primary_evidence | M6: Sí | N6: No | O6: https://elcongresista.mx/politica/chihuahua/mario-garcia-2027
A7: 21 | B7: SMEE-20260803-7A52522F | C7: El Congresista | D7: Evaluarán votación en Ceresos para elecciones de 2027 en Chihuahua | E7: 46237.643 | F7: Chihuahua | G7: Chihuahua | H7: PAN | I7: Otro evento electoral | J7: classified | K7: No | L7: primary_evidence | M7: Sí | N7: No | O7: https://elcongresista.mx/politica/chihuahua/votacion-ceresos-chihuahua-2027
A8: 2 | C8: Central Electoral INE | D8: FIMI: la amenaza contra las democracias que no respeta fronteras | E8: 46237.625 | I8: Otro evento electoral | J8: review | K8: Sí | M8: No | N8: No | O8: https://centralelectoral.ine.mx/2026/08/03/fimi-informe-ue/ | P8: Certeza INE
A9: 22 | B9: SMEE-20260803-A2EAB4CA | C9: El Congresista | D9: David Cortés impulsa alianzas y unidad en el PAN de Morelia | E9: 46237.608 | F9: Michoacán | G9: Morelia | H9: PAN | I9: Otro evento electoral | J9: classified | K9: No | L9: primary_evidence | M9: Sí | N9: No | O9: https://elcongresista.mx/politica/michoacan/david-cortes-unidad-pan-morelia-2027
A10: 50 | B10: SMEE-20260803-E6C5BB3F | C10: El Universal Estados | D10: Ulises Mejía Haro consolida ventaja hacia gubernatura | El Universal | E10: 46237.6 | J10: duplicate | K10: No | L10: duplicate | M10: No | N10: Sí | O10: https://www.eluniversal.com.mx/estados/ulises-mejia-haro-consolida-ventaja-hacia-gubernatura/
A11: 49 | B11: SMEE-20260803-49BC2B07 | C11: Expansión Política | D11: Los gobernadores que ya eligieron a su sucesor para 2027: quiénes son los respaldados en los estados | E11: 46237.6 | J11: duplicate | K11: No | L11: duplicate | M11: No | N11: Sí | O11: https://politica.expansion.mx/mexico/2026/07/28/gobernadores-eligieron-su-sucesor-elecciones-2027
A12: 48 | B12: SMEE-20260803-5A7E410C | C12: El Universal | D12: Morena se reúne con aspirantes a candidaturas para gobernador de Chihuahua, Sinaloa, Sonora y BC | E12: 46237.6 | J12: duplicate | K12: No | L12: duplicate | M12: No | N12: Sí | O12: https://www.eluniversal.com.mx/nacion/morena-se-reune-con-aspirantes-a-candidaturas-para-gobernador-chihuahua-sinaloa-y-sonora-entre-ellos/
A13: 47 | B13: SMEE-20260803-21D35497 | C13: El Universal | D13: “No son tiempos”: Colosio Riojas descarta adelantarse rumbo a una posible candidatura; informará decisión a finales de 2026, dice | E13: 46237.599 | F13: Nuevo León | H13: Movimiento Ciudadano | I13: Otro evento electoral | J13: review | K13: Sí | L13: primary_evidence | M13: Sí | N13: No | O13: https://www.eluniversal.com.mx/nacion/no-son-tiempos-colosio-riojas-descarta-adelantarse-rumbo-a-una-posible-candidatura-informara-decision-a-finales-de-2026-dice/ | P13: Erick Moctezuma
A14: 46 | B14: SMEE-20260803-E6C5BB3F | C14: El Universal Estados | D14: Ulises Mejía Haro consolida ventaja hacia gubernatura | El Universal | E14: 46237.598 | J14: duplicate | K14: No | L14: duplicate | M14: No | N14: Sí | O14: https://www.eluniversal.com.mx/estados/ulises-mejia-haro-consolida-ventaja-hacia-gubernatura/
A15: 45 | B15: SMEE-20260803-49BC2B07 | C15: Expansión Política | D15: Los gobernadores que ya eligieron a su sucesor para 2027: quiénes son los respaldados en los estados | E15: 46237.598 | J15: duplicate | K15: No | L15: duplicate | M15: No | N15: Sí | O15: https://politica.expansion.mx/mexico/2026/07/28/gobernadores-eligieron-su-sucesor-elecciones-2027
A16: 44 | B16: SMEE-20260803-5A7E410C | C16: El Universal | D16: Morena se reúne con aspirantes a candidaturas para gobernador de Chihuahua, Sinaloa, Sonora y BC | E16: 46237.598 | J16: duplicate | K16: No | L16: duplicate | M16: No | N16: Sí | O16: https://www.eluniversal.com.mx/nacion/morena-se-reune-con-aspirantes-a-candidaturas-para-gobernador-chihuahua-sinaloa-y-sonora-entre-ellos/
A17: 42 | B17: SMEE-20260803-E6C5BB3F | C17: El Universal Estados | D17: Ulises Mejía Haro consolida ventaja hacia gubernatura | El Universal | E17: 46237.595 | F17: Zacatecas | G17: Zacatecas | H17: Morena | I17: Registro o anuncio de candidatura | J17: review | K17: Sí | L17: primary_evidence | M17: Sí | N17: No | O17: https://www.eluniversal.com.mx/estados/ulises-mejia-haro-consolida-ventaja-hacia-gubernatura/
A18: 41 | B18: SMEE-20260803-49BC2B07 | C18: Expansión Política | D18: Los gobernadores que ya eligieron a su sucesor para 2027: quiénes son los respaldados en los estados | E18: 46237.595 | F18: Michoacán | H18: Morena | I18: Otro evento electoral | J18: review | K18: Sí | L18: primary_evidence | M18: Sí | N18: No | O18: https://politica.expansion.mx/mexico/2026/07/28/gobernadores-eligieron-su-sucesor-elecciones-2027
A19: 40 | B19: SMEE-20260803-5A7E410C | C19: El Universal | D19: Morena se reúne con aspirantes a candidaturas para gobernador de Chihuahua, Sinaloa, Sonora y BC | E19: 46237.595 | F19: Chihuahua | G19: Chihuahua | H19: Morena | I19: Otro evento electoral | J19: review | K19: Sí | L19: primary_evidence | M19: Sí | N19: No | O19: https://www.eluniversal.com.mx/nacion/morena-se-reune-con-aspirantes-a-candidaturas-para-gobernador-chihuahua-sinaloa-y-sonora-entre-ellos/
A20: 23 | B20: SMEE-20260803-8F80E3E5 | C20: El Congresista | D20: PAN define estrategias electorales: Santiago De la Peña para Chihuahua | E20: 46237.577 | F20: Chihuahua | G20: Chihuahua | H20: PAN | I20: Otro evento electoral | J20: classified | K20: No | L20: primary_evidence | M20: Sí | N20: No | O20: https://elcongresista.mx/politica/chihuahua/pan-candidatos-electorales-chihuahua-2027
A21: 38 | C21: El Universal Nación | D21: Aspirantes seleccionados en examen de la unam bloquean insurgentes exigen respetar resultados de evaluacion en linea | E21: 46237.568 | J21: review | K21: Sí | M21: No | N21: No | O21: https://www.eluniversal.com.mx/nacion/aspirantes-seleccionados-en-examen-de-la-unam-bloquean-insurgentes-exigen-respetar-resultados-de-evaluacion-en-linea/
A22: 12 | C22: El Norte | D22: PAN reporta 140 registros para coordinadores en NL | E22: 46237.559 | F22: Nuevo León | H22: PAN | J22: review | K22: Sí | M22: No | N22: No | O22: https://www.elnorte.com/pan-reporta-140-registros-para-coordinadores-en-nl/ar3251593 | P22: Ángel Charles
A23: 13 | C23: El Universal | D23: Analistas mejoran pronóstico del PIB para este año, según encuesta de Banxico; SHCP ya lo había anticipado | E23: 46237.551 | J23: review | K23: Sí | M23: No | N23: No | O23: https://www.eluniversal.com.mx/cartera/analistas-mejoran-pronostico-del-pib-para-este-ano-segun-encuesta-de-banxico-shcp-ya-lo-habia-anticipado/ | P23: Leonor Flores null
A24: 14 | C24: El Universal | D24: Edson Álvarez despierta interés en Europa: estos son los tres clubes que lo buscan | E24: 46237.548 | J24: review | K24: Sí | M24: No | N24: No | O24: https://www.eluniversal.com.mx/deportes/edson-alvarez-despierta-interes-en-europa-estos-son-los-tres-clubes-que-lo-buscan/ | P24: Leobardo Vázquez Hernández
A25: 15 | C25: El Universal | D25: Sheinbaum alista reunión con Sección 22 de la CNTE sobre acuerdos en Oaxaca; prevé arranque de consulta escuela por escuela | E25: 46237.452 | F25: Oaxaca | J25: review | K25: Sí | M25: No | N25: No | O25: https://www.eluniversal.com.mx/nacion/sheinbaum-alista-reunion-con-seccion-22-de-la-cnte-sobre-acuerdos-en-oaxaca-preve-arranque-de-consulta-escuela-por-escuela/ | P25: Salvador Corona, Pedro Villa y Caña
A26: 24 | B26: SMEE-20260803-79036C52 | C26: El Congresista | D26: Candidaturas de Morena se afianzan en Chihuahua con nuevos registros | E26: 46237.424 | F26: Chihuahua | G26: Chihuahua | H26: Morena | I26: Otro evento electoral | J26: review | K26: Sí | L26: primary_evidence | M26: Sí | N26: No | O26: https://elcongresista.mx/politica/chihuahua/morena-chihuahua-registros-candidaturas
A27: 25 | C27: El Congresista | D27: Pemex cierra Pozo Krem-1 y continúa con programas de salud | E27: 46237.325 | F27: Veracruz | G27: Veracruz | J27: review | K27: Sí | M27: No | N27: No | O27: https://elcongresista.mx/politica/veracruz/pemex-cierra-pozo-krem-1-salud-benedicto-juarez
A28: 26 | B28: SMEE-20260803-F0C70DA7 | C28: El Congresista | D28: Morena establece nueva evaluación de candidatos para 2027 | E28: 46237.306 | F28: Puebla | G28: Puebla | H28: Morena | I28: Otro evento electoral | J28: classified | K28: No | L28: primary_evidence | M28: Sí | N28: No | O28: https://elcongresista.mx/politica/puebla/morena-filtro-candidatos-puebla-2027
A29: 27 | B29: SMEE-20260803-C31C484D | C29: El Congresista | D29: Andrés Manuel López Beltrán recorre Distrito 6 de Tabasco | E29: 46237.235 | F29: Tabasco | H29: Morena | I29: Otro evento electoral | J29: classified | K29: No | L29: primary_evidence | M29: Sí | N29: No | O29: https://elcongresista.mx/politica/nacional/andres-manuel-lopez-beltran-recorrido-tabasco
A30: 28 | C30: El Congresista | D30: PT traza estrategia electoral hacia 2027 en Encerrona Nacional | E30: 46237.129 | H30: Partido del Trabajo | J30: review | K30: Sí | M30: No | N30: No | O30: https://elcongresista.mx/politica/nacional/encerrona-nacional-pt-2027
A31: 11 | C31: El Financiero | D31: ‘Andy’ López Beltrán inicia gira ‘casa por casa’ por diputación en Tabasco | E31: 46237.101 | F31: Tabasco | H31: Morena | J31: review | K31: Sí | M31: No | N31: No | O31: https://www.elfinanciero.com.mx/estados/2026/08/02/andy-lopez-beltran-inicia-gira-casa-por-casa-por-diputacion-en-tabasco/ | P31: Redacción
A32: 29 | B32: SMEE-20260803-C9DFFDB0 | C32: El Congresista | D32: Andy López Beltrán inicia su camino hacia diputación federal en Tabasco | E32: 46237.064 | F32: Tabasco | H32: Morena | I32: Otro evento electoral | J32: classified | K32: No | L32: primary_evidence | M32: Sí | N32: No | O32: https://elcongresista.mx/politica/nacional/andy-lopez-beltran-diputado-tabasco
A33: 30 | B33: SMEE-20260803-DF903415 | C33: El Congresista | D33: Carlos Torres Piña consolida su liderazgo en Morelia con 2 mil asistentes | E33: 46237.056 | F33: Michoacán | G33: Morelia | I33: Otro evento electoral | J33: classified | K33: No | L33: primary_evidence | M33: Sí | N33: No | O33: https://elcongresista.mx/politica/michoacan/torres-pina-liderazgo-morelia
A34: 31 | C34: El Congresista | D34: Coahuila y Manolo Jiménez sobresalen en aprobación estatal nacional | E34: 46237.054 | F34: Coahuila | J34: review | K34: Sí | M34: No | N34: No | O34: https://elcongresista.mx/politica/coahuila/coahuila-manolo-jimenez-aprobacion
A35: 32 | B35: SMEE-20260802-8E279CC1 | C35: El Congresista | D35: Cuatro finalistas de Morena avanzan a la encuesta estatal en CDMX | E35: 46236.954 | F35: Ciudad de México | H35: Morena | I35: Nueva encuesta | J35: classified | K35: No | L35: primary_evidence | M35: Sí | N35: No | O35: https://elcongresista.mx/politica/nacional/cuatro-finalistas-morena-encuesta-coordinacion-estatal
A36: 3 | C36: Central Electoral INE | D36: Fortalecen Coordinación Interinstitucional en Materia de Búsqueda de Personas en Durango | E36: 46236.854 | F36: Durango | G36: Durango | J36: review | K36: Sí | M36: No | N36: No | O36: https://centralelectoral.ine.mx/2026/08/02/fortalecen-coordinacion-interinstitucional-en-materia-de-busqueda-de-personas-en-durango/ | P36: Redacción INE
A37: 33 | B37: SMEE-20260802-9DEC0C3C | C37: El Congresista | D37: Nuevo León: morenistas inician contienda por gubernatura 2027 | E37: 46236.713 | F37: Nuevo León | H37: Morena | I37: Registro o anuncio de candidatura | J37: classified | K37: No | L37: primary_evidence | M37: Sí | N37: No | O37: https://elcongresista.mx/politica/nuevo-leon/nuevo-leon-morenistas-candidatura-gubernatura-2027
A38: 4 | C38: Central Electoral INE | D38: Firma INE San Luis Potosí convenio con la Secretaría de Seguridad y Protección Ciudadana para impulsar la credencialización de personas privadas de la libertad | E38: 46236.625 | F38: San Luis Potosí | G38: San Luis Potosí | J38: review | K38: Sí | M38: No | N38: No | O38: https://centralelectoral.ine.mx/2026/08/02/firma-ine-san-luis-potosi-convenio-con-la-secretaria-de-seguridad-y-proteccion-ciudadana-para-impulsar-la-credencializacion-de-personas-privadas-de-la-libertad/ | P38: Redacción INE
A39: 34 | B39: SMEE-20260802-5E507918 | C39: El Congresista | D39: Unidad interna en Morena busca fortalecer candidatura en Chihuahua | E39: 46236.432 | F39: Chihuahua | G39: Chihuahua | H39: Morena | I39: Otro evento electoral | J39: review | K39: Sí | L39: primary_evidence | M39: Sí | N39: No | O39: https://elcongresista.mx/politica/chihuahua/unidad-morena-chihuahua-2027
A40: 35 | C40: El Congresista | D40: Somos México alcanza 11 mil afiliados en Chihuahua, asegura Paty Terrazas | E40: 46236.422 | F40: Chihuahua | G40: Chihuahua | J40: review | K40: Sí | M40: No | N40: No | O40: https://elcongresista.mx/politica/chihuahua/somos-mexico-afiliados-chihuahua
...

Sheet Actores
A1: Código del evento | B1: Evento | C1: Actor | D1: Tipo | E1: Partido | F1: Estado | G1: Prioritario
A2: SMEE-20260801-FC0313F6 | B2: Planeará y organizará INE más de 500 actividades del Proceso Electoral Federal 2026‑2027 | C2: Instituto Nacional Electoral | D2: institution | G2: No
A3: SMEE-20260803-5A7E410C | B3: Morena se reúne con aspirantes a candidaturas para gobernador de Chihuahua, Sinaloa, Sonora y BC | C3: Instituto Nacional Electoral | D3: institution | G3: No

Sheet Revisión manual
A1: ID | B1: Título | C1: Fuente | D1: Estado | E1: Tipo de evento | F1: Motivos de revisión | G1: URL
A2: 47 | B2: “No son tiempos”: Colosio Riojas descarta adelantarse rumbo a una posible candidatura; informará decisión a finales de 2026, dice | C2: El Universal | D2: Nuevo León | E2: Otro evento electoral | F2: Se detectaron varias entidades con fuerza similar · Varios tipos de evento obtuvieron puntuaciones equivalentes | G2: https://www.eluniversal.com.mx/nacion/no-son-tiempos-colosio-riojas-descarta-adelantarse-rumbo-a-una-posible-candidatura-informara-decision-a-finales-de-2026-dice/
A3: 43 | B3: Entrevista del Consejero Electoral Uuc-kib Espadas con Carlos Zúñiga para Milenio TV | C3: Central Electoral INE | F3: No se alcanzó el umbral para clasificar el tipo de evento · No se detectó una entidad federativa · Falta el tipo de evento o una fecha verificable | G3: https://centralelectoral.ine.mx/2026/08/03/entrevista-del-consejero-electoral-uuc-kib-espadas-con-carlos-zuniga-para-milenio-tv-5/
A4: 42 | B4: Ulises Mejía Haro consolida ventaja hacia gubernatura | El Universal | C4: El Universal Estados | D4: Zacatecas | E4: Registro o anuncio de candidatura | F4: Varios tipos de evento obtuvieron puntuaciones equivalentes | G4: https://www.eluniversal.com.mx/estados/ulises-mejia-haro-consolida-ventaja-hacia-gubernatura/
A5: 41 | B5: Los gobernadores que ya eligieron a su sucesor para 2027: quiénes son los respaldados en los estados | C5: Expansión Política | D5: Michoacán | E5: Otro evento electoral | F5: Varios tipos de evento obtuvieron puntuaciones equivalentes | G5: https://politica.expansion.mx/mexico/2026/07/28/gobernadores-eligieron-su-sucesor-elecciones-2027
A6: 40 | B6: Morena se reúne con aspirantes a candidaturas para gobernador de Chihuahua, Sinaloa, Sonora y BC | C6: El Universal | D6: Chihuahua | E6: Otro evento electoral | F6: Se detectaron varias entidades con fuerza similar | G6: https://www.eluniversal.com.mx/nacion/morena-se-reune-con-aspirantes-a-candidaturas-para-gobernador-chihuahua-sinaloa-y-sonora-entre-ellos/
A7: 39 | B7: Territorium retiene evidencias de trampas en examen de la unam contrato la faculta para almacenar audio y video de aspirantes | C7: El Universal Nación | F7: No se alcanzó el umbral para clasificar el tipo de evento · No se detectó una entidad federativa · Falta el tipo de evento o una fecha verificable | G7: https://www.eluniversal.com.mx/nacion/territorium-retiene-evidencias-de-trampas-en-examen-de-la-unam-contrato-la-faculta-para-almacenar-audio-y-video-de-aspirantes/
A8: 38 | B8: Aspirantes seleccionados en examen de la unam bloquean insurgentes exigen respetar resultados de evaluacion en linea | C8: El Universal Nación | F8: No se alcanzó el umbral para clasificar el tipo de evento · No se detectó una entidad federativa · Falta el tipo de evento o una fecha verificable | G8: https://www.eluniversal.com.mx/nacion/aspirantes-seleccionados-en-examen-de-la-unam-bloquean-insurgentes-exigen-respetar-resultados-de-evaluacion-en-linea/
A9: 36 | B9: Homenaje póstumo a Claudio Bres Garza en Coahuila | C9: El Congresista | D9: Coahuila | F9: No se alcanzó el umbral para clasificar el tipo de evento · Falta el tipo de evento o una fecha verificable | G9: https://elcongresista.mx/politica/coahuila/homenaje-claudio-bres-garza-coahuila
A10: 35 | B10: Somos México alcanza 11 mil afiliados en Chihuahua, asegura Paty Terrazas | C10: El Congresista | D10: Chihuahua | F10: No se alcanzó el umbral para clasificar el tipo de evento · Falta el tipo de evento o una fecha verificable | G10: https://elcongresista.mx/politica/chihuahua/somos-mexico-afiliados-chihuahua
A11: 34 | B11: Unidad interna en Morena busca fortalecer candidatura en Chihuahua | C11: El Congresista | D11: Chihuahua | E11: Otro evento electoral | F11: Varios tipos de evento obtuvieron puntuaciones equivalentes | G11: https://elcongresista.mx/politica/chihuahua/unidad-morena-chihuahua-2027
A12: 31 | B12: Coahuila y Manolo Jiménez sobresalen en aprobación estatal nacional | C12: El Congresista | D12: Coahuila | F12: No se alcanzó el umbral para clasificar el tipo de evento · Falta el tipo de evento o una fecha verificable | G12: https://elcongresista.mx/politica/coahuila/coahuila-manolo-jimenez-aprobacion
A13: 28 | B13: PT traza estrategia electoral hacia 2027 en Encerrona Nacional | C13: El Congresista | F13: No se alcanzó el umbral para clasificar el tipo de evento · No se detectó una entidad federativa · Falta el tipo de evento o una fecha verificable | G13: https://elcongresista.mx/politica/nacional/encerrona-nacional-pt-2027
A14: 25 | B14: Pemex cierra Pozo Krem-1 y continúa con programas de salud | C14: El Congresista | D14: Veracruz | F14: No se alcanzó el umbral para clasificar el tipo de evento · Falta el tipo de evento o una fecha verificable | G14: https://elcongresista.mx/politica/veracruz/pemex-cierra-pozo-krem-1-salud-benedicto-juarez
A15: 24 | B15: Candidaturas de Morena se afianzan en Chihuahua con nuevos registros | C15: El Congresista | D15: Chihuahua | E15: Otro evento electoral | F15: Varios tipos de evento obtuvieron puntuaciones equivalentes | G15: https://elcongresista.mx/politica/chihuahua/morena-chihuahua-registros-candidaturas
A16: 18 | B16: Morena definirá coordinador de la 4T en Sonora a finales de agosto | C16: El Congresista | D16: Sonora | F16: No se alcanzó el umbral para clasificar el tipo de evento · Falta el tipo de evento o una fecha verificable | G16: https://elcongresista.mx/politica/sonora/morena-sonora-encuesta-coordinador-agosto
A17: 17 | B17: ¿Quiénes son los aspirantes a candidatos de Morena para Sonora? | C17: Expansión Política | D17: Sonora | F17: No se alcanzó el umbral para clasificar el tipo de evento · Falta el tipo de evento o una fecha verificable | G17: https://politica.expansion.mx/estados/2026/08/01/quienes-son-aspirantes-candidatos-morena-sonora
A18: 16 | B18: ¿Quiénes son los aspirantes a candidatos de Morena para Nayarit? | C18: Expansión Política | D18: Nayarit | F18: No se alcanzó el umbral para clasificar el tipo de evento · Falta el tipo de evento o una fecha verificable | G18: https://politica.expansion.mx/estados/2026/08/01/quienes-son-los-aspirantes-a-candidatos-de-morena-para-nayarit
A19: 15 | B19: Sheinbaum alista reunión con Sección 22 de la CNTE sobre acuerdos en Oaxaca; prevé arranque de consulta escuela por escuela | C19: El Universal | D19: Oaxaca | F19: No se alcanzó el umbral para clasificar el tipo de evento · Falta el tipo de evento o una fecha verificable | G19: https://www.eluniversal.com.mx/nacion/sheinbaum-alista-reunion-con-seccion-22-de-la-cnte-sobre-acuerdos-en-oaxaca-preve-arranque-de-consulta-escuela-por-escuela/
A20: 14 | B20: Edson Álvarez despierta interés en Europa: estos son los tres clubes que lo buscan | C20: El Universal | F20: No se alcanzó el umbral para clasificar el tipo de evento · No se detectó una entidad federativa · Falta el tipo de evento o una fecha verificable | G20: https://www.eluniversal.com.mx/deportes/edson-alvarez-despierta-interes-en-europa-estos-son-los-tres-clubes-que-lo-buscan/
A21: 13 | B21: Analistas mejoran pronóstico del PIB para este año, según encuesta de Banxico; SHCP ya lo había anticipado | C21: El Universal | F21: No se alcanzó el umbral para clasificar el tipo de evento · No se detectó una entidad federativa · Falta el tipo de evento o una fecha verificable | G21: https://www.eluniversal.com.mx/cartera/analistas-mejoran-pronostico-del-pib-para-este-ano-segun-encuesta-de-banxico-shcp-ya-lo-habia-anticipado/
A22: 12 | B22: PAN reporta 140 registros para coordinadores en NL | C22: El Norte | D22: Nuevo León | F22: No se alcanzó el umbral para clasificar el tipo de evento · Falta el tipo de evento o una fecha verificable | G22: https://www.elnorte.com/pan-reporta-140-registros-para-coordinadores-en-nl/ar3251593
A23: 11 | B23: ‘Andy’ López Beltrán inicia gira ‘casa por casa’ por diputación en Tabasco | C23: El Financiero | D23: Tabasco | F23: No se alcanzó el umbral para clasificar el tipo de evento · Falta el tipo de evento o una fecha verificable | G23: https://www.elfinanciero.com.mx/estados/2026/08/02/andy-lopez-beltran-inicia-gira-casa-por-casa-por-diputacion-en-tabasco/
A24: 10 | B24: Entrevista del Consejero Electoral Uuc-kib Espadas con Verónica Méndez para W Radio | C24: Central Electoral INE | E24: Otro evento electoral | F24: No se detectó una entidad federativa · Falta entidad o ámbito geográfico | G24: https://centralelectoral.ine.mx/2026/07/31/entrevista-del-consejero-electoral-uuc-kib-espadas-con-veronica-mendez-para-w-radio/
A25: 8 | B25: Aprueba Comisión de Vinculación el calendario de entrevistas para personas aspirantes a Presidencias y Consejerías Electorales de Organismos Públicos Locales | C25: Central Electoral INE | F25: No se alcanzó el umbral para clasificar el tipo de evento · No se detectó una entidad federativa · Falta el tipo de evento o una fecha verificable | G25: https://centralelectoral.ine.mx/2026/07/31/aprueba-comision-de-vinculacion-el-calendario-de-entrevistas-para-personas-aspirantes-a-presidencias-y-consejerias-electorales-de-organismos-publicos-locales/
A26: 7 | B26: Abre INE convocatoria para ingresar al Servicio Profesional Electoral en plazas de Institutos Electorales Estatales | C26: Central Electoral INE | F26: No se alcanzó el umbral para clasificar el tipo de evento · No se detectó una entidad federativa · Falta el tipo de evento o una fecha verificable | G26: https://centralelectoral.ine.mx/2026/08/01/abre-ine-convocatoria-para-ingresar-al-servicio-profesional-electoral-en-plazas-de-institutos-electorales-estatales/
A27: 6 | B27: Convocan a la ciudadanía tabasqueña a participar en el concurso público del sistema OPLE | C27: Central Electoral INE | D27: Tabasco | F27: No se alcanzó el umbral para clasificar el tipo de evento · Falta el tipo de evento o una fecha verificable | G27: https://centralelectoral.ine.mx/2026/08/01/convocan-a-la-ciudadania-tabasquena-a-participar-en-el-concurso-publico-del-sistema-ople/
A28: 5 | B28: El INE concluye con éxito la aplicación de la prueba psicométrica del Concurso Público para ingresar al SPEN en todo el país | C28: Central Electoral INE | F28: No se alcanzó el umbral para clasificar el tipo de evento · No se detectó una entidad federativa · Falta el tipo de evento o una fecha verificable | G28: https://centralelectoral.ine.mx/2026/08/01/el-ine-concluye-con-exito-la-aplicacion-de-la-prueba-psicometrica-del-concurso-publico-para-ingresar-al-spen-en-todo-el-pais/
A29: 4 | B29: Firma INE San Luis Potosí convenio con la Secretaría de Seguridad y Protección Ciudadana para impulsar la credencialización de personas privadas de la libertad | C29: Central Electoral INE | D29: San Luis Potosí | F29: No se alcanzó el umbral para clasificar el tipo de evento · Falta el tipo de evento o una fecha verificable | G29: https://centralelectoral.ine.mx/2026/08/02/firma-ine-san-luis-potosi-convenio-con-la-secretaria-de-seguridad-y-proteccion-ciudadana-para-impulsar-la-credencializacion-de-personas-privadas-de-la-libertad/
A30: 3 | B30: Fortalecen Coordinación Interinstitucional en Materia de Búsqueda de Personas en Durango | C30: Central Electoral INE | D30: Durango | F30: No se alcanzó el umbral para clasificar el tipo de evento · Falta el tipo de evento o una fecha verificable | G30: https://centralelectoral.ine.mx/2026/08/02/fortalecen-coordinacion-interinstitucional-en-materia-de-busqueda-de-personas-en-durango/
A31: 2 | B31: FIMI: la amenaza contra las democracias que no respeta fronteras | C31: Central Electoral INE | E31: Otro evento electoral | F31: No se detectó una entidad federativa · Falta entidad o ámbito geográfico | G31: https://centralelectoral.ine.mx/2026/08/03/fimi-informe-ue/
A32: 1 | B32: Invita INE Michoacán a la ciudadanía a recoger su Credencial para Votar | C32: Central Electoral INE | D32: Michoacán | F32: No se alcanzó el umbral para clasificar el tipo de evento · Falta el tipo de evento o una fecha verificable | G32: https://centralelectoral.ine.mx/2026/08/03/invita-ine-michoacan-a-la-ciudadania-a-recoger-su-credencial-para-votar/

Sheet Fuentes
A1: ID | B1: Fuente | C1: Tipo | D1: Estado base | E1: Confiabilidad | F1: Activa | G1: URL base | H1: Publicaciones recopiladas
A2: 1 | B2: Central Electoral INE | C2: official | E2: high | F2: Sí | G2: https://centralelectoral.ine.mx | H2: =COUNTIF('Publicaciones'!$C$2:$C$51,B2)
A3: 9 | B3: Diario del Norte | C3: media | D3: Chihuahua | E3: medium | F3: Sí | G3: https://diariodelnorte.example | H3: =COUNTIF('Publicaciones'!$C$2:$C$51,B3)
A4: 7 | B4: El Congresista | C4: media | E4: medium | F4: Sí | G4: https://elcongresista.mx | H4: =COUNTIF('Publicaciones'!$C$2:$C$51,B4)
A5: 2 | B5: El Financiero | C5: media | E5: medium | F5: Sí | G5: https://www.elfinanciero.com.mx | H5: =COUNTIF('Publicaciones'!$C$2:$C$51,B5)
A6: 8 | B6: El Norte | C6: media | D6: Nuevo León | E6: high | F6: Sí | G6: https://www.elnorte.com | H6: =COUNTIF('Publicaciones'!$C$2:$C$51,B6)
A7: 3 | B7: El Universal | C7: media | E7: high | F7: Sí | G7: https://www.eluniversal.com.mx | H7: =COUNTIF('Publicaciones'!$C$2:$C$51,B7)
A8: 4 | B8: El Universal Estados | C8: media | E8: high | F8: Sí | G8: https://www.eluniversal.com.mx/estados | H8: =COUNTIF('Publicaciones'!$C$2:$C$51,B8)
A9: 5 | B9: El Universal Nación | C9: media | E9: high | F9: Sí | G9: https://www.eluniversal.com.mx/nacion | H9: =COUNTIF('Publicaciones'!$C$2:$C$51,B9)
A10: 10 | B10: Encuestadora Horizonte | C10: pollster | E10: high | F10: Sí | G10: https://horizonte.example | H10: =COUNTIF('Publicaciones'!$C$2:$C$51,B10)
A11: 6 | B11: Expansión Política | C11: media | E11: high | F11: Sí | G11: https://politica.expansion.mx | H11: =COUNTIF('Publicaciones'!$C$2:$C$51,B11)
A12: 11 | B12: Noticias de Occidente | C12: media | D12: Jalisco | E12: medium | F12: Sí | G12: https://occidente.example | H12: =COUNTIF('Publicaciones'!$C$2:$C$51,B12)
A13: 13 | B13: Panorama Nacional | C13: media | E13: medium | F13: Sí | G13: https://panorama.example | H13: =COUNTIF('Publicaciones'!$C$2:$C$51,B13)
A14: 12 | B14: Tribunal Electoral | C14: official | E14: high | F14: Sí | G14: https://www.te.gob.mx | H14: =COUNTIF('Publicaciones'!$C$2:$C$51,B14)
